Workbook

Sheet Package Status
A1: Completion Rates
B2: Pass | C2: Fail | D2: Concern | E2: Confirm - Corrected | F2: N/A
A3: System | B3: =COUNTIF('P-ISSM_Checklist'!E5:E76, "pass") -> 0 | C3: =COUNTIF('P-ISSM_Checklist'!E5:E76, "fail") -> 0 | D3: =COUNTIF('P-ISSM_Checklist'!E5:E76, "concern") -> 0 | E3: =COUNTIF('P-ISSM_Checklist'!E5:E76, "confirm - corrected") -> 0 | F3: =COUNTIF('P-ISSM_Checklist'!E5:E76, "n/a") -> 0
A4: Controls | B4: =COUNTIF('P-ISSM_Checklist'!E78:E105, "pass") -> 0 | C4: =COUNTIF('P-ISSM_Checklist'!E78:E105, "fail") -> 0 | D4: =COUNTIF('P-ISSM_Checklist'!E78:E105, "concern") -> 0 | E4: =COUNTIF('P-ISSM_Checklist'!E78:E105, "confirm - corrected") -> 0 | F4: =COUNTIF('P-ISSM_Checklist'!E78:E105, "n/a") -> 0
A5: Assets | B5: =COUNTIF('P-ISSM_Checklist'!E107:E134, "pass") -> 0 | C5: =COUNTIF('P-ISSM_Checklist'!E107:E134, "fail") -> 0 | D5: =COUNTIF('P-ISSM_Checklist'!E107:E134, "concern") -> 0 | E5: =COUNTIF('P-ISSM_Checklist'!E107:E134, "Confirm - Corrected") -> 0 | F5: =COUNTIF('P-ISSM_Checklist'!E107:E134, "n/a") -> 0
A6: POA&Ms | B6: =COUNTIF('P-ISSM_Checklist'!E136:E156, "pass") -> 0 | C6: =COUNTIF('P-ISSM_Checklist'!E136:E156, "fail") -> 0 | D6: =COUNTIF('P-ISSM_Checklist'!E136:E156, "concern") -> 0 | E6: =COUNTIF('P-ISSM_Checklist'!E136:E156, "confirm - corrected") -> 0 | F6: =COUNTIF('P-ISSM_Checklist'!E136:E156, "n/a") -> 0
A7: Artifacts | B7: =COUNTIF('P-ISSM_Checklist'!E158:E171, "pass") -> 0 | C7: =COUNTIF('P-ISSM_Checklist'!E158:E171, "fail") -> 0 | D7: =COUNTIF('P-ISSM_Checklist'!E158:E171, "concern") -> 0 | E7: =COUNTIF('P-ISSM_Checklist'!E158:E171, "confirm - corrected") -> 0 | F7: =COUNTIF('P-ISSM_Checklist'!E158:E171, "n/a") -> 0
A8: Package | B8: =COUNTIF('P-ISSM_Checklist'!E173:E174, "pass") -> 0 | C8: =COUNTIF('P-ISSM_Checklist'!E173:E174, "fail") -> 0 | D8: =COUNTIF('P-ISSM_Checklist'!E173:E174, "concern") -> 0 | E8: =COUNTIF('P-ISSM_Checklist'!E173:E174, "confirm - corrected") -> 0 | F8: =COUNTIF('P-ISSM_Checklist'!E173:E174, "n/a") -> 0
A9: Relationships | B9: =COUNTIF('P-ISSM_Checklist'!E176:E186, "pass") -> 0 | C9: =COUNTIF('P-ISSM_Checklist'!E176:E186, "fail") -> 0 | D9: =COUNTIF('P-ISSM_Checklist'!E176:E186, "concern") -> 0 | E9: =COUNTIF('P-ISSM_Checklist'!E176:E186, "confirm - corrected") -> 0 | F9: =COUNTIF('P-ISSM_Checklist'!E176:E186, "n/a") -> 0
A10: Management | B10: =COUNTIF('P-ISSM_Checklist'!E188:E199, "pass") -> 0 | C10: =COUNTIF('P-ISSM_Checklist'!E188:E199, "fail") -> 0 | D10: =COUNTIF('P-ISSM_Checklist'!E188:E199, "concern") -> 0 | E10: =COUNTIF('P-ISSM_Checklist'!E188:E199, "confirm - corrected") -> 0 | F10: =COUNTIF('P-ISSM_Checklist'!E188:E199, "n/a") -> 0
A11: Total Pass | B11: =B3+B4+B5+B6+B7+B8+B9+B10 -> 0 | C11: =B11/175 -> 0
A12: Total Fail | B12: =C3+C4+C5+C6+C7+C8+C9+C10 -> 0 | C12: =B12/175 -> 0
A13: Total Concern | B13: =D3+D4+D5+D6+D7+D8+D9+D10 -> 0 | C13: =B13/175 -> 0
A14: Confirm - Corrected | B14: =E3+E4+E5+E6+E7+E8+E9+E10 -> 0 | C14: =B14/175 -> 0
A15: Total N/A | B15: =F3+F4+F5+F6+F7+F8+F9+F10 -> 0 | C15: =B15/175 -> 0
A16: Total Complete | B16: =B11+B12+B13+B14+B15 -> 0 | C16: =B16/175 -> 0

Sheet P-ISSM_Checklist
B1: TECTIX SYSTEM ASSESSMENT CHECKLIST & INSTRUCTIONS
B2: Purpose: Provide a checklist with instructions to aid in reviewing system packages (A&A, Assess Only, SP, POAM) in eMASS for discrepancies. Checks considered returnable for rework by TECTIX are identified. Checks also include references for additional guidance on where to make corrections.
A3: Tabs | B3: Requirement | C3: Package Type | D3: Package Review Check | E3: Result | F3: Returnable for Rework? | G3: ISSM Comment | H3: ISSM Recommendation | I3: Status | J3: ISO/PM Evidence & Comments
B4: Details: System Information
A5: =HYPERLINK("#'Chk Instructions-Where to Look'!A2", "System") -> System | B5: eMASS Required Fields | D5: If Assess Only, System 'Mission Criticality' and CIA values adhere to the Assess Only Approval path documented in section 4, figure 2 of the Assess Only TTP? | F5: No-Add to Terms & Conditions
A6: =HYPERLINK("#'Chk Instructions-Where to Look'!A3", "System") -> System | B6: Entrance Criteria | D6: Workflow title has the correct Naming Convention | F6: ISO - On the Spot Correction Suffices
A7: =HYPERLINK("#'Chk Instructions-Where to Look'!A4", "System") -> System | B7: Required Field in eMASS | C7: SP | D7: eMASS 'System Name' matches Data 'Item Name' | F7: ISO - On the Spot Correction Suffices
A8: =HYPERLINK("#'Chk Instructions-Where to Look'!A5","System") -> System | B8: Required Field in eMASS | C8: SP | D8: eMASS 'Acronym' matches Data 'Acronym' | F8: ISO - On the Spot Correction Suffices
A9: =HYPERLINK("#'Chk Instructions-Where to Look'!A6", "System") -> System | B9: Autopopulated by eMASS | C9: SP | D9: Authorization Termination Date' inline with Data | F9: No Further Action Required
A10: =HYPERLINK("#'Chk Instructions-Where to Look'!A7", "System") -> System | B10: Required Field in eMASS | C10: SP | D10: 'National Security System' matches Data and ITS *the Privacy Overlay should be applied if the NSS processes, stores or transmits PII'* | F10: No-Add to Terms & Conditions
A11: =HYPERLINK("#'Chk Instructions-Where to Look'!A8", "System") -> System | B11: Entrance Criteria | C11: SP | D11: National Security System' checklist filled out completely? | F11: No-Add to Terms & Conditions
A12: =HYPERLINK("#'Chk Instructions-Where to Look'!A9", "System") -> System | B12: Entrance Criteria | C12: SP | D12: 'Financial Management System' matches Data 'Account System Feeder' *verify the Financial Management Overlay is applied if 'yes'* | F12: No-Add to Terms & Conditions
A13: =HYPERLINK("#'Chk Instructions-Where to Look'!A10", "System") -> System | B13: Entrance Criteria | C13: SP | D13: If 'Public Facing Component / Presence:' is Yes; does the Auth Boundary identify the public facing component/capability, IP & FQDN provided, Whitelisted and Publicly accessible? | F13: No-Add to Terms & Conditions
A14: =HYPERLINK("#'Chk Instructions-Where to Look'!A11", "System") -> System | B14: Entrance Criteria | C14: SP | D14: Systems contains CUI, PII and/or PHI and matches Data? If System contains CUI, the Confidentiality and Integrity must be MODERATE or HIGH. | F14: ISO - On the Spot Correction Suffices
A15: =HYPERLINK("#'Chk Instructions-Where to Look'!A12", "System") -> System | B15: Required Field in eMASS | C15: SP | D15: 'System Description' matches Data 'Description' (no deviations allowed) | F15: ISO - On the Spot Correction Suffices
A16: =HYPERLINK("#'Chk Instructions-Where to Look'!A13", "System") -> System | B16: Required Field in eMASS | C16: SP | D16: 'Data ID' matches eMASS 'Data' Number | F16: ISO - On the Spot Correction Suffices
A17: =HYPERLINK("#'Chk Instructions-Where to Look'!A14", "System") -> System | B17: Required Field in eMASS | C17: SP | D17: System User Categories' Identify roles, responsibilities and categories for system *confirm if Foreign Nationals are authorized to use the system* | F17: No-Add to Terms & Conditions
A18: =HYPERLINK("#'Chk Instructions-Where to Look'!A15", "System") -> System | B18: Entrance Criteria | C18: SP | D18: Is this a Cloud Computer? Does the Cloud Computer' match the Infrastructure section in Data *confirm correct Cloud Type & Service Model are selected if applicable* | F18: ISO - On the Spot Correction Suffices
A19: =HYPERLINK("#'Chk Instructions-Where to Look'!A16", "System") -> System | B19: Entrance Criteria | C19: SP | D19: Does the commercial cloud system have an Impact Level 4 or 5: Controlled Unclassified Information and Unclassified National Security Information (U-NSI) | F19: Yes
A20: =HYPERLINK("#'Chk Instructions-Where to Look'!A17", "System") -> System | B20: Entrance Criteria | C20: SP | D20: Does the Cloud Service Offering (CSO) have a current PA? Does the CSO have a pending submission for PA? Does the CSO have a FEDRAMP approval? | F20: Yes
A21: =HYPERLINK("#'Chk Instructions-Where to Look'!A18", "System") -> System | B21: Required Field in eMASS | C21: SP | D21: 'PPSM Registry Number' Provided *required for SaaS (all impact levels)* | F21: ISO - On the Spot Correction Suffices
A22: =HYPERLINK("#'Chk Instructions-Where to Look'!A19", "System") -> System | B22: Entrance Criteria | C22: SP | D22: System Authorization Boundary' has an Executive Summary on the System Details tab, the Artifact is Linked or attached, and has a date less than 1 year old. *review Cloud checks if applicable* | F22: Yes
A23: =HYPERLINK("#'Chk Instructions-Where to Look'!A20", "System") -> System | B23: Entrance Criteria | C23: SP | D23: Are the HW & SW Baselines populated? ''Hardware / Software / Firmware' has an Executive Summary on the System Details tab, the Artifact Linked or attached, and has a date less than 1 year old. *template must be used to meet requirement* | F23: Yes
A24: =HYPERLINK("#'Chk Instructions-Where to Look'!A21", "System") -> System | B24: Entrance Criteria | C24: SP | D24: 'System Enterprise and Information Security Architecture' has an Executive Summary on the System Details tab, the Artifact is Linked or attached, and has a date less than 1 year old. | F24: No - Add to Terms & Conditions
A25: =HYPERLINK("#'Chk Instructions-Where to Look'!A22", "System") -> System | B25: Entrance Criteria | C25: SP | D25: 'Information Flows / Paths' has an Executive Summary on the System Details tab, the Artifact is Linked or attached, and has a date less than 1 year old. | F25: No - Add to Terms & Conditions
A26: =HYPERLINK("#'Chk Instructions-Where to Look'!A23", "System") -> System | B26: Cloud Review Check | D26: Is there a clear depiction of the Cloud Service Provider (CSP) / CSO within the Network Topology Diagrams? | F26: Yes
A27: =HYPERLINK("#'Chk Instructions-Where to Look'!A24", "System") -> System | B27: Cloud Review Check | D27: Does the Network Topology Diagrams show connection of the CSP to customers via Cloud Access Point (CAP) for sensitive data (CUI as handled at Impact Levels 4/5 or classified information up to SECRET as handled at Level 6)? NOTE: IL 4/5 - A Boundary CAP (BCAP) is required to connect off-premises non-DoD (commercially or governmentally) owned and operated CSOs to the DISN (or other DoD networks). | F27: Yes
A28: =HYPERLINK("#'Chk Instructions-Where to Look'!A25", "System") -> System | B28: Cloud Review Check | D28: Does the Network Topology Diagrams align with the cloud service model? | F28: Yes
A29: =HYPERLINK("#'Chk Instructions-Where to Look'!A26", "System") -> System | B29: Cloud Review Check | D29: Is there an entry in the DMZ whitelist? | F29: Yes
A30: =HYPERLINK("#'Chk Instructions-Where to Look'!A27", "System") -> System | B30: Required Field in eMASS | C30: SP | D30: 'Network Connection Rules' provided? If yes, artifact such as ISA provided? | F30: ISO - On the Spot Correction Suffices
A31: =HYPERLINK("#'Chk Instructions-Where to Look'!A28", "System") -> System | B31: Required Field in eMASS | C31: SP | D31: Interconnected Information Systems and Identifiers’ provided? If yes, artifact such as ISA provided? NOTE: CSD ISA template is available. | F31: ISO - On the Spot Correction Suffices
A32: =HYPERLINK("#'Chk Instructions-Where to Look'!A29", "System") -> System | B32: Entrance Criteria | C32: SP | D32: Encryption Techniques' provided to protect DAR and DIT [CUI/PII/PH data] | F32: Yes
A33: =HYPERLINK("#'Chk Instructions-Where to Look'!A30", "System") -> System | B33: Required Field in eMASS | C33: SP | D33: 'Cryptographic Key Management Information' (e.g., public key infrastructures, certificate authorities, EKMS, KMI, etc.) | F33: Yes
A34: =HYPERLINK("#'Chk Instructions-Where to Look'!A31", "System") -> System | B34: AMC Entrance Criteria | D34: Does system have a registration in the Authorizing Official Repository (AO-R)? | F34: Yes
B35: System Details: System Location
A36: =HYPERLINK("#'Chk Instructions-Where to Look'!A32", "System") -> System | B36: Required Field in eMASS | C36: SP | D36: System Location' is correct | F36: ISO - On the Spot Correction Suffices
A37: =HYPERLINK("#'Chk Instructions-Where to Look'!A33", "System") -> System | B37: Required Field in eMASS | D37: 'Deployment Locations' Provided | F37: ISO - On the Spot Correction Suffices
A38: =HYPERLINK("#'Chk Instructions-Where to Look'!A34", "System") -> System | B38: Not a Required Field in eMASS | D38: Baseline Location' Provided | F38: ISO - On the Spot Correction Suffices
A39: =HYPERLINK("#'Chk Instructions-Where to Look'!A35", "System") -> System | B39: Required Field in eMASS | C39: SP | D39: Physical Location(s)' Provided | F39: ISO - On the Spot Correction Suffices
B40: System Details: Authorization Information
...

Sheet ISSM Responses
A1: Fixed
A2: POA&M

Sheet Responses
A1: Pass | B1: 30 Day Check | C1: No | D1: Corrections Required
A2: Fail | B2: 60 Day Check | C2: yes | D2: No Further Action Required
A3: Concern | B3: 90 Day Check | C3: Maybe
A4: N/A | B4: 120 Day Check
A5: Confirm - Corrected | B5: 150 Day Check
A6: Previously Corrected | B6: 180 Day Check
A7: Not Yet Assessed | B7: 210 Day Check
